<?xml version="1.0"?>
<robot name="tiger" xmlns:xacro="http://www.ros.org/wiki/xacro">

	<xacro:include filename="$(find tiger_description)/urdf/config.xacro" />
	<xacro:include filename="$(find tiger_description)/urdf/imu_macro.xacro" />
	<xacro:include filename="$(find tiger_description)/urdf/materials.gazebo" />
	<xacro:include filename="$(find tiger_description)/urdf/tiger_prefix.gazebo" />

  <link name="world"/>
  <joint name="floating" type="floating">
	  <parent link ="world"/>
	  <child link ="base_link"/>
  </joint>

  <!-- Base Link -->
  <link name="base_link">
    <collision>
      <origin xyz="0 0 0" rpy="0 0 0"/>
      <geometry>
        <mesh filename = "package://tiger_description/meshes/centered_origin_m_collision.dae"/>
      </geometry>"
    </collision>

    <visual>
      <origin xyz="0 0 0" rpy="0 0 0"/>
      <geometry>
        <mesh filename = "package://tiger_description/meshes/centered_origin_m.dae"/>
      </geometry>
      <material name="red"/>
    </visual>
 
    <inertial>
      <origin xyz="-.005751 .191679 .012699" rpy="0 0 0"/>
      <mass value="66.073"/>
      <inertia
        ixx="9.936780816" ixy="-0.026400619" ixz="0.215368542"
        iyy="12.921961991" iyz="0.065728938"
        izz="4.616020311"/>
    </inertial>
  </link>
  <!-- wheel 1 -->
  <link name="FR_wheel_link1">
    <collision>
      <origin xyz="0 0 0" rpy="0 0 0"/>
      <geometry>
        <!--<cylinder radius=".183" length="0.134"/>-->
        <mesh filename="package://tiger_description/meshes/centered_wheel_m_collision.dae"/>
      </geometry>
    </collision>

    <visual>
      <origin xyz="0 0 0" rpy="0 0 0"/>
      <geometry>
        <mesh filename="package://tiger_description/meshes/centered_wheel_m.dae"/>
      </geometry>
      <!--material name="orange"/>-->
    </visual>

    <inertial>
      <origin xyz="0 0 0" rpy="0 0 0"/>
      <mass value="4.018025"/>
      <inertia
        ixx="0.0222747923" ixy="-0.0" ixz="0.0"
        iyy="0.02096655598" iyz="-0.0"
        izz="0.03219387057"/>
    </inertial>
  </link>

  <joint name="base_link_FR_wheel_link_joint1" type="continuous">
     <origin xyz="0.597494 0 0.49925" rpy="0 0 0"/>
     <parent link="base_link"/>
     <child link="FR_wheel_link1"/>
     <axis xyz = "1 0 0" />

     <calibration rising="0.0"/>
     <dynamics damping="0.0" friction="0.0"/>
     <limit effort="30" velocity="1.0" lower="-2.2" upper="0.7" />
     <safety_controller k_velocity="10" k_position="15" soft_lower_limit="-2.0" soft_upper_limit="0.5" />
  </joint>

	<transmission name="base_link_FR_wheel_link_simple_trans1">
		<type>transmission_interface/SimpleTransmission</type>
		<joint name="base_link_FR_wheel_link_joint1">
			<hardwareInterface>hardware_interface/EffortJointInterface</hardwareInterface>
		</joint>
		<actuator name="base_link_FR_wheel_link_motor1">
			<mechanicalReduction>1</mechanicalReduction> <!-- specify if needed -->
		</actuator>
	</transmission>

 <!-- wheel 2 -->
  <link name="FR_wheel_link2">
    <collision>
      <origin xyz="0 0 0" rpy="0 0 0"/>
      <geometry>
        <!--<cylinder radius=".183" length="0.134"/>-->
        <mesh filename="package://tiger_description/meshes/centered_wheel_m_collision.dae"/>
      </geometry>
    </collision>

    <visual>
      <origin xyz="0 0 0" rpy="0 0 0"/>
      <geometry>
        <mesh filename="package://tiger_description/meshes/centered_wheel_m.dae"/>
      </geometry>
      <!--material name="orange"/>-->
    </visual>

    <inertial>
      <origin xyz="0 0 0" rpy="0 0 0"/>
      <mass value="4.018025"/>
      <inertia
        ixx="0.0222747923" ixy="-0.0" ixz="0.0"
        iyy="0.02096655598" iyz="-0.0"
        izz="0.03219387057"/>
    </inertial>
  </link>

  <joint name="base_link_FR_wheel_link_joint2" type="continuous">
     <origin xyz="-0.597494 0 0.49925" rpy="0 0 0"/>
     <parent link="base_link"/>
     <child link="FR_wheel_link2"/>
     <axis xyz = "1 0 0" />

     <calibration rising="0.0"/>
     <dynamics damping="0.0" friction="0.0"/>
     <limit effort="30" velocity="1.0" lower="-2.2" upper="0.7" />
     <safety_controller k_velocity="10" k_position="15" soft_lower_limit="-2.0" soft_upper_limit="0.5" />
  </joint>

	<transmission name="base_link_FR_wheel_link_simple_trans2">
		<type>transmission_interface/SimpleTransmission</type>
		<joint name="base_link_FR_wheel_link_joint2">
			<hardwareInterface>hardware_interface/EffortJointInterface</hardwareInterface>
		</joint>
		<actuator name="base_link_FR_wheel_link_motor2">
			<mechanicalReduction>1</mechanicalReduction> <!-- specify if needed -->
		</actuator>
	</transmission>

 <!-- wheel 3 -->
  <link name="FR_wheel_link3">
    <collision>
      <origin xyz="0 0 0" rpy="0 0 0"/>
      <geometry>
        <!--<cylinder radius=".183" length="0.134"/>-->
        <mesh filename="package://tiger_description/meshes/centered_wheel_m_collision.dae"/>
      </geometry>
    </collision>

    <visual>
      <origin xyz="0 0 0" rpy="0 0 0"/>
      <geometry>
        <mesh filename="package://tiger_description/meshes/centered_wheel_m.dae"/>
      </geometry>
      <!--material name="orange"/>-->
    </visual>

    <inertial>
      <origin xyz="0 0 0" rpy="0 0 0"/>
      <mass value="4.018025"/>
      <inertia
        ixx="0.0222747923" ixy="-0.0" ixz="0.0"
        iyy="0.02096655598" iyz="-0.0"
        izz="0.03219387057"/>
    </inertial>
  </link>

  <joint name="base_link_FR_wheel_link_joint3" type="continuous">
     <origin xyz="0.597494 0 -0.49925" rpy="0 0 0"/>
     <parent link="base_link"/>
     <child link="FR_wheel_link3"/>
     <axis xyz = "1 0 0" />

     <calibration rising="0.0"/>
     <dynamics damping="0.0" friction="0.0"/>
     <limit effort="30" velocity="1.0" lower="-2.2" upper="0.7" />
     <safety_controller k_velocity="10" k_position="15" soft_lower_limit="-2.0" soft_upper_limit="0.5" />
  </joint>

	<transmission name="base_link_FR_wheel_link_simple_trans3">
		<type>transmission_interface/SimpleTransmission</type>
		<joint name="base_link_FR_wheel_link_joint3">
			<hardwareInterface>hardware_interface/EffortJointInterface</hardwareInterface>
		</joint>
		<actuator name="base_link_FR_wheel_link_motor3">
			<mechanicalReduction>1</mechanicalReduction> <!-- specify if needed -->
		</actuator>
	</transmission>

 <!-- wheel 4 -->
  <link name="FR_wheel_link4">
    <collision>
      <origin xyz="0 0 0" rpy="0 0 0"/>
      <geometry>
        <!--<cylinder radius=".183" length="0.134"/>-->
        <mesh filename="package://tiger_description/meshes/centered_wheel_m_collision.dae"/>
      </geometry>
    </collision>

    <visual>
      <origin xyz="0 0 0" rpy="0 0 0"/>
      <geometry>
        <mesh filename="package://tiger_description/meshes/centered_wheel_m.dae"/>
      </geometry>
      <!--material name="orange"/>-->
    </visual>

    <inertial>
      <origin xyz="0 0 0" rpy="0 0 0"/>
      <mass value="4.018025"/>
      <inertia
        ixx="0.0222747923" ixy="-0.0" ixz="0.0"
        iyy="0.02096655598" iyz="-0.0"
        izz="0.03219387057"/>
    </inertial>
  </link>

  <joint name="base_link_FR_wheel_link_joint4" type="continuous">
     <origin xyz="-0.597494 0 -0.49925" rpy="0 0 0"/>
     <parent link="base_link"/>
     <child link="FR_wheel_link4"/>
     <axis xyz = "1 0 0" />

     <calibration rising="0.0"/>
     <dynamics damping="0.0" friction="0.0"/>
     <limit effort="30" velocity="1.0" lower="-2.2" upper="0.7" />
     <safety_controller k_velocity="10" k_position="15" soft_lower_limit="-2.0" soft_upper_limit="0.5" />
  </joint>

	<transmission name="base_link_FR_wheel_link_simple_trans4">
		<type>transmission_interface/SimpleTransmission</type>
		<joint name="base_link_FR_wheel_link_joint4">
			<hardwareInterface>hardware_interface/EffortJointInterface</hardwareInterface>
		</joint>
		<actuator name="base_link_FR_wheel_link_motor4">
			<mechanicalReduction>1</mechanicalReduction> <!-- specify if needed -->
		</actuator>
	</transmission>

  <!--sensors-->
  <xacro:imu_sensor xyz="0 0.35 0" rpy="${M_PI/2} 0 0" parent="base_link" />


</robot>
